```js
//模拟网络请求失败
function fetch() {
  return new Promise((resolve, reject) => {
    setTimeout(() => reject('err'), 1000);
  });
}
//load函数接受一个onError函数
function load(onError) {
  const p = fetch();
  return p.catch(err => {
    return new Promise((resolve, reject) => {
      const retry = () => resolve(load(onError)); //关键：当resolve函数的参数是promise时,则上一行new promise的状态取决于这个参数promise
      const fail = () => reject(err);
      onError(retry, fail);
    });
  });
}
//使用
load(retry => {
  //失败后重试
  retry();
}).then(res => {
  //成功
  console.log(res);
});
```js
